LAST SEEN   TYPE      REASON                     OBJECT                                            MESSAGE
16d         Warning   UnexpectedAdmissionError   pod/vllm-qwen25-coder-14b-awq-855dd959c7-sxctw    Allocate failed due to no healthy devices present; cannot allocate unhealthy devices nvidia.com/gpu, which is unexpected
16d         Warning   FailedMount                pod/vllm-qwen25-coder-14b-awq-855dd959c7-sxctw    MountVolume.SetUp failed for volume "kube-api-access-lzjcj" : object "llm-recovery-lab"/"kube-root-ca.crt" not registered
16d         Warning   FailedScheduling           pod/vllm-qwen25-coder-14b-awq-855dd959c7-t6csq    0/1 nodes are available: 1 Insufficient nvidia.com/gpu. no new claims to deallocate, preemption: 0/1 nodes are available: 1 Preemption is not helpful for scheduling.
16d         Normal    Scheduled                  pod/vllm-qwen25-coder-14b-awq-855dd959c7-t6csq    Successfully assigned llm-recovery-lab/vllm-qwen25-coder-14b-awq-855dd959c7-t6csq to k8s-llm-gpu-01
16d         Normal    SuccessfulCreate           replicaset/vllm-qwen25-coder-14b-awq-855dd959c7   Created pod: vllm-qwen25-coder-14b-awq-855dd959c7-t6csq
16d         Normal    Pulled                     pod/vllm-qwen25-coder-14b-awq-855dd959c7-t6csq    Container image "vllm/vllm-openai@sha256:c2914767605584b6d8f45686b82de173ecc99e781897aa3d0a66dacd72c51ae1" already present on machine and can be accessed by the pod
16d         Normal    Created                    pod/vllm-qwen25-coder-14b-awq-855dd959c7-t6csq    Container created
16d         Normal    Started                    pod/vllm-qwen25-coder-14b-awq-855dd959c7-t6csq    Container started
16d         Warning   Unhealthy                  pod/vllm-qwen25-coder-14b-awq-855dd959c7-t6csq    Startup probe failed: Get "http://10.244.0.74:8000/health": dial tcp 10.244.0.74:8000: connect: connection refused
16d         Warning   UnexpectedAdmissionError   pod/vllm-qwen25-coder-14b-awq-855dd959c7-t6csq    Allocate failed due to no healthy devices present; cannot allocate unhealthy devices nvidia.com/gpu, which is unexpected
16d         Warning   FailedMount                pod/vllm-qwen25-coder-14b-awq-855dd959c7-t6csq    MountVolume.SetUp failed for volume "kube-api-access-mtdsw" : object "llm-recovery-lab"/"kube-root-ca.crt" not registered
16d         Warning   FailedScheduling           pod/vllm-qwen25-coder-14b-awq-855dd959c7-fg86z    0/1 nodes are available: 1 Insufficient nvidia.com/gpu. no new claims to deallocate, preemption: 0/1 nodes are available: 1 Preemption is not helpful for scheduling.
16d         Normal    SuccessfulCreate           replicaset/vllm-qwen25-coder-14b-awq-855dd959c7   Created pod: vllm-qwen25-coder-14b-awq-855dd959c7-fg86z
16d         Normal    Scheduled                  pod/vllm-qwen25-coder-14b-awq-855dd959c7-fg86z    Successfully assigned llm-recovery-lab/vllm-qwen25-coder-14b-awq-855dd959c7-fg86z to k8s-llm-gpu-01
16d         Normal    Pulled                     pod/vllm-qwen25-coder-14b-awq-855dd959c7-fg86z    Container image "vllm/vllm-openai@sha256:c2914767605584b6d8f45686b82de173ecc99e781897aa3d0a66dacd72c51ae1" already present on machine and can be accessed by the pod
16d         Normal    Created                    pod/vllm-qwen25-coder-14b-awq-855dd959c7-fg86z    Container created
16d         Normal    Started                    pod/vllm-qwen25-coder-14b-awq-855dd959c7-fg86z    Container started
16d         Warning   Unhealthy                  pod/vllm-qwen25-coder-14b-awq-855dd959c7-fg86z    Startup probe failed: Get "http://10.244.0.111:8000/health": dial tcp 10.244.0.111:8000: connect: connection refused
5d1h        Warning   UnexpectedAdmissionError   pod/vllm-qwen25-coder-14b-awq-855dd959c7-fg86z    Allocate failed due to no healthy devices present; cannot allocate unhealthy devices nvidia.com/gpu, which is unexpected
5d1h        Warning   FailedMount                pod/vllm-qwen25-coder-14b-awq-855dd959c7-fg86z    MountVolume.SetUp failed for volume "kube-api-access-x67bn" : object "llm-recovery-lab"/"kube-root-ca.crt" not registered
5d1h        Normal    SuccessfulCreate           replicaset/vllm-qwen25-coder-14b-awq-855dd959c7   Created pod: vllm-qwen25-coder-14b-awq-855dd959c7-m7nwx
5d1h        Warning   FailedScheduling           pod/vllm-qwen25-coder-14b-awq-855dd959c7-m7nwx    0/1 nodes are available: 1 Insufficient nvidia.com/gpu. no new claims to deallocate, preemption: 0/1 nodes are available: 1 Preemption is not helpful for scheduling.
5d1h        Normal    Scheduled                  pod/vllm-qwen25-coder-14b-awq-855dd959c7-m7nwx    Successfully assigned llm-recovery-lab/vllm-qwen25-coder-14b-awq-855dd959c7-m7nwx to k8s-llm-gpu-01
5d1h        Normal    Created                    pod/vllm-qwen25-coder-14b-awq-855dd959c7-m7nwx    Container created
5d1h        Normal    Pulled                     pod/vllm-qwen25-coder-14b-awq-855dd959c7-m7nwx    Container image "vllm/vllm-openai@sha256:c2914767605584b6d8f45686b82de173ecc99e781897aa3d0a66dacd72c51ae1" already present on machine and can be accessed by the pod
5d1h        Normal    Started                    pod/vllm-qwen25-coder-14b-awq-855dd959c7-m7nwx    Container started
5d1h        Warning   Unhealthy                  pod/vllm-qwen25-coder-14b-awq-855dd959c7-m7nwx    Startup probe failed: Get "http://10.244.0.149:8000/health": dial tcp 10.244.0.149:8000: connect: connection refused
33m         Warning   UnexpectedAdmissionError   pod/vllm-qwen25-coder-14b-awq-855dd959c7-m7nwx    Allocate failed due to no healthy devices present; cannot allocate unhealthy devices nvidia.com/gpu, which is unexpected
33m         Warning   FailedMount                pod/vllm-qwen25-coder-14b-awq-855dd959c7-m7nwx    MountVolume.SetUp failed for volume "kube-api-access-tvbqq" : object "llm-recovery-lab"/"kube-root-ca.crt" not registered
33m         Warning   FailedScheduling           pod/vllm-qwen25-coder-14b-awq-855dd959c7-h5d7g    0/1 nodes are available: 1 Insufficient nvidia.com/gpu. no new claims to deallocate, preemption: 0/1 nodes are available: 1 Preemption is not helpful for scheduling.
33m         Normal    SuccessfulCreate           replicaset/vllm-qwen25-coder-14b-awq-855dd959c7   Created pod: vllm-qwen25-coder-14b-awq-855dd959c7-h5d7g
32m         Normal    Pulled                     pod/vllm-qwen25-coder-14b-awq-855dd959c7-h5d7g    Container image "vllm/vllm-openai@sha256:c2914767605584b6d8f45686b82de173ecc99e781897aa3d0a66dacd72c51ae1" already present on machine and can be accessed by the pod
32m         Normal    Scheduled                  pod/vllm-qwen25-coder-14b-awq-855dd959c7-h5d7g    Successfully assigned llm-recovery-lab/vllm-qwen25-coder-14b-awq-855dd959c7-h5d7g to k8s-llm-gpu-01
32m         Normal    Created                    pod/vllm-qwen25-coder-14b-awq-855dd959c7-h5d7g    Container created
32m         Normal    Started                    pod/vllm-qwen25-coder-14b-awq-855dd959c7-h5d7g    Container started
32m         Warning   Unhealthy                  pod/vllm-qwen25-coder-14b-awq-855dd959c7-h5d7g    Startup probe failed: Get "http://10.244.0.185:8000/health": dial tcp 10.244.0.185:8000: connect: connection refused
32m         Normal    ScalingReplicaSet          deployment/vllm-qwen25-coder-14b-awq              Scaled down replica set vllm-qwen25-coder-14b-awq-855dd959c7 from 1 to 0
32m         Normal    Killing                    pod/vllm-qwen25-coder-14b-awq-855dd959c7-h5d7g    Stopping container vllm
32m         Normal    SuccessfulDelete           replicaset/vllm-qwen25-coder-14b-awq-855dd959c7   Deleted pod: vllm-qwen25-coder-14b-awq-855dd959c7-h5d7g
24m         Normal    Scheduled                  pod/stage-qwen3-14b-awq-hkbkc                     Successfully assigned llm-recovery-lab/stage-qwen3-14b-awq-hkbkc to k8s-llm-gpu-01
24m         Normal    SuccessfulCreate           job/stage-qwen3-14b-awq                           Created pod: stage-qwen3-14b-awq-hkbkc
24m         Normal    Started                    pod/stage-qwen3-14b-awq-hkbkc                     Container started
24m         Normal    Created                    pod/stage-qwen3-14b-awq-hkbkc                     Container created
24m         Normal    Pulled                     pod/stage-qwen3-14b-awq-hkbkc                     Container image "vllm/vllm-openai@sha256:c2914767605584b6d8f45686b82de173ecc99e781897aa3d0a66dacd72c51ae1" already present on machine and can be accessed by the pod
22m         Normal    Completed                  job/stage-qwen3-14b-awq                           Job completed
20m         Normal    Scheduled                  pod/vllm-qwen3-14b-awq-5bdbfdbc46-6sj9f           Successfully assigned llm-recovery-lab/vllm-qwen3-14b-awq-5bdbfdbc46-6sj9f to k8s-llm-gpu-01
20m         Normal    Pulled                     pod/vllm-qwen3-14b-awq-5bdbfdbc46-6sj9f           Container image "vllm/vllm-openai@sha256:c2914767605584b6d8f45686b82de173ecc99e781897aa3d0a66dacd72c51ae1" already present on machine and can be accessed by the pod
20m         Normal    Created                    pod/vllm-qwen3-14b-awq-5bdbfdbc46-6sj9f           Container created
20m         Normal    ScalingReplicaSet          deployment/vllm-qwen3-14b-awq                     Scaled up replica set vllm-qwen3-14b-awq-5bdbfdbc46 from 0 to 1
20m         Normal    SuccessfulCreate           replicaset/vllm-qwen3-14b-awq-5bdbfdbc46          Created pod: vllm-qwen3-14b-awq-5bdbfdbc46-6sj9f
20m         Normal    Started                    pod/vllm-qwen3-14b-awq-5bdbfdbc46-6sj9f           Container started
17m         Warning   Unhealthy                  pod/vllm-qwen3-14b-awq-5bdbfdbc46-6sj9f           Startup probe failed: Get "http://10.244.0.187:8000/health": dial tcp 10.244.0.187:8000: connect: connection refused
5m59s       Warning   FailedScheduling           pod/vllm-qwen3-14b-awq-5bdbfdbc46-q7b6j           0/1 nodes are available: 1 Insufficient nvidia.com/gpu. no new claims to deallocate, preemption: 0/1 nodes are available: 1 No preemption victims found for incoming pod.
5m59s       Normal    Killing                    pod/vllm-qwen3-14b-awq-5bdbfdbc46-6sj9f           Stopping container vllm
5m59s       Normal    SuccessfulCreate           replicaset/vllm-qwen3-14b-awq-5bdbfdbc46          Created pod: vllm-qwen3-14b-awq-5bdbfdbc46-q7b6j
5m58s       Warning   Unhealthy                  pod/vllm-qwen3-14b-awq-5bdbfdbc46-6sj9f           Readiness probe failed: Get "http://10.244.0.187:8000/health": dial tcp 10.244.0.187:8000: connect: connection refused
5m58s       Normal    Scheduled                  pod/vllm-qwen3-14b-awq-5bdbfdbc46-q7b6j           Successfully assigned llm-recovery-lab/vllm-qwen3-14b-awq-5bdbfdbc46-q7b6j to k8s-llm-gpu-01
5m57s       Normal    Pulled                     pod/vllm-qwen3-14b-awq-5bdbfdbc46-q7b6j           Container image "vllm/vllm-openai@sha256:c2914767605584b6d8f45686b82de173ecc99e781897aa3d0a66dacd72c51ae1" already present on machine and can be accessed by the pod
5m57s       Normal    Created                    pod/vllm-qwen3-14b-awq-5bdbfdbc46-q7b6j           Container created
5m57s       Normal    Started                    pod/vllm-qwen3-14b-awq-5bdbfdbc46-q7b6j           Container started
4m37s       Warning   Unhealthy                  pod/vllm-qwen3-14b-awq-5bdbfdbc46-q7b6j           Startup probe failed: Get "http://10.244.0.188:8000/health": dial tcp 10.244.0.188:8000: connect: connection refused
93s         Normal    Killing                    pod/vllm-qwen3-14b-awq-5bdbfdbc46-q7b6j           Stopping container vllm
93s         Warning   FailedScheduling           pod/vllm-qwen3-14b-awq-5bdbfdbc46-s47ck           0/1 nodes are available: 1 Insufficient nvidia.com/gpu. no new claims to deallocate, preemption: 0/1 nodes are available: 1 No preemption victims found for incoming pod.
93s         Normal    SuccessfulCreate           replicaset/vllm-qwen3-14b-awq-5bdbfdbc46          Created pod: vllm-qwen3-14b-awq-5bdbfdbc46-s47ck
92s         Warning   Unhealthy                  pod/vllm-qwen3-14b-awq-5bdbfdbc46-q7b6j           Readiness probe failed: Get "http://10.244.0.188:8000/health": dial tcp 10.244.0.188:8000: connect: connection refused
91s         Normal    Scheduled                  pod/vllm-qwen3-14b-awq-5bdbfdbc46-s47ck           Successfully assigned llm-recovery-lab/vllm-qwen3-14b-awq-5bdbfdbc46-s47ck to k8s-llm-gpu-01
91s         Normal    Created                    pod/vllm-qwen3-14b-awq-5bdbfdbc46-s47ck           Container created
91s         Normal    Pulled                     pod/vllm-qwen3-14b-awq-5bdbfdbc46-s47ck           Container image "vllm/vllm-openai@sha256:c2914767605584b6d8f45686b82de173ecc99e781897aa3d0a66dacd72c51ae1" already present on machine and can be accessed by the pod
90s         Normal    Started                    pod/vllm-qwen3-14b-awq-5bdbfdbc46-s47ck           Container started
11s         Warning   Unhealthy                  pod/vllm-qwen3-14b-awq-5bdbfdbc46-s47ck           Startup probe failed: Get "http://10.244.0.189:8000/health": dial tcp 10.244.0.189:8000: connect: connection refused
